test_delete_queue (__main__.TestExercice) ... FAIL
test_delete_stack (__main__.TestExercice) ... ERROR
test_reverse (__main__.TestExercice) ... FAIL
test_sort_queue (__main__.TestExercice) ... FAIL
test_sort_stack (__main__.TestExercice) ... FAIL
test_string_and_structs (__main__.TestExercice) ... ERROR

======================================================================
ERROR: test_delete_stack (__main__.TestExercice)
----------------------------------------------------------------------
Traceback (most recent call last):
  File "test_exercice.py", line 33, in test_delete_stack
    output = exercice.delete_nth_from_stack(lifo, len(lifo) - 1)
  File "/home/runner/work/c01_ch6_exercices_3-DavidPotvin-jpg/c01_ch6_exercices_3-DavidPotvin-jpg/exercice.py", line 25, in delete_nth_from_stack
    for i in range(data):
TypeError: 'Stack' object cannot be interpreted as an integer

======================================================================
ERROR: test_string_and_structs (__main__.TestExercice)
----------------------------------------------------------------------
Traceback (most recent call last):
  File "test_exercice.py", line 91, in test_string_and_structs
    fifo.put_many("Yeet")
TypeError: put_many() missing 1 required positional argument: 'items'

======================================================================
FAIL: test_delete_queue (__main__.TestExercice)
----------------------------------------------------------------------
Traceback (most recent call last):
  File "test_exercice.py", line 53, in test_delete_queue
    'Mauvaise reponse'
AssertionError: 0 != [1, 2, 3, 4, 5, 6, 7, 8, 9, 10, 11, 12, 13, 14, 15, 16, 17, 18, 19] : Mauvaise reponse

======================================================================
FAIL: test_reverse (__main__.TestExercice)
----------------------------------------------------------------------
Traceback (most recent call last):
  File "test_exercice.py", line 23, in test_reverse
    'Mauvaise reponse'
AssertionError: First sequence is not a list: None

======================================================================
FAIL: test_sort_queue (__main__.TestExercice)
----------------------------------------------------------------------
Traceback (most recent call last):
  File "test_exercice.py", line 83, in test_sort_queue
    'Mauvaise reponse'
AssertionError: [55, [30 chars]48, 260, 451, 508, 511, 617, 631, 634, 654, 749, 935, 950, 963] != [55, [30 chars]48, 260, 451, 508, 511, 617, 631, 634, 654, 749, 935, 950, 963] : Mauvaise reponse

======================================================================
FAIL: test_sort_stack (__main__.TestExercice)
----------------------------------------------------------------------
Traceback (most recent call last):
  File "test_exercice.py", line 68, in test_sort_stack
    'Mauvaise reponse'
AssertionError: [67, [31 chars]68, 623, 719, 770, 777, 824, 865, 873, 874, 913, 926, 928, 943] != [67, [31 chars]68, 623, 719, 770, 777, 824, 865, 873, 874, 913, 926, 928, 943] : Mauvaise reponse

----------------------------------------------------------------------
Ran 6 tests in 0.002s

FAILED (failures=4, errors=2)
